Workbook

Sheet Qtr1
A1: Immunization Services for Infants and Children
A2: Fully Immunized Children & Completely Immunized Children
A3: Philippines, 2025 1st Quarter
A5: PSGC 10 | B5: Region, Province/City, and Municipality | C5: Projected Population (0-12 months old) (Previous cohort) | D5: FIC | H5: Projected population 0-12 months (previous cohort) minus previous FIC | I5: CIC
D6: Male | E6: Female | F6: Total | G6: % | I6: Male | J6: Female | K6: Total | L6: %
B7: PHILIPPINES | C7: 2392392 | D7: 186915 | E7: 180760 | F7: 367675 | G7: 15.36851 | H7: 840855 | I7: 25154 | J7: 23263 | K7: 48417 | L7: 5.7580677
A8: 1300000000 | B8: NCR | C8: 285798 | D8: 26952 | E8: 26307 | F8: 53259 | G8: 18.63519 | H8: 60578 | I8: 3869 | J8: 3668 | K8: 7537 | L8: 12.441811
A9: 1380100000 | B9: City of Caloocan | C9: 36488 | D9: 3002 | E9: 2894 | F9: 5896 | G9: 16.158737 | H9: 10459 | I9: 157 | J9: 110 | K9: 267 | L9: 2.5528253 | N9: Complete
A10: 1380200000 | B10: City of Las Piñas | C10: 12284 | D10: 1154 | E10: 1176 | F10: 2330 | G10: 18.967763 | H10: 2457 | I10: 206 | J10: 202 | K10: 408 | L10: 16.605617
A11: 1380300000 | B11: City of Makati | C11: 4580 | D11: 570 | E11: 530 | F11: 1100 | G11: 24.017467 | H11: 269 | I11: 18 | J11: 18 | K11: 36 | L11: 13.3829
A12: 1380400000 | B12: City of Malabon | C12: 8070 | D12: 565 | E12: 526 | F12: 1091 | G12: 13.519207 | H12: 1806 | I12: 129 | J12: 128 | K12: 257 | L12: 14.230343
A13: 1380500000 | B13: City of Mandaluyong | C13: 8672 | D13: 1009 | E13: 1041 | F13: 2050 | G13: 23.639299 | H13: 318 | I13: 279 | J13: 290 | K13: 569 | L13: 178.93082
A14: 1380600000 | B14: City of Manila | C14: 37288 | D14: 3976 | E14: 3897 | F14: 7873 | G14: 21.114031 | H14: 1758 | I14: 507 | J14: 495 | K14: 1002 | L14: 56.996587
A15: 1380700000 | B15: City of Marikina | C15: 9135 | D15: 399 | E15: 379 | F15: 778 | G15: 8.516694 | H15: 5810 | I15: 97 | J15: 77 | K15: 174 | L15: 2.9948365
A16: 1380800000 | B16: City of Muntinlupa | C16: 10788 | D16: 460 | E16: 490 | F16: 950 | G16: 8.8060808 | H16: 4892 | I16: 160 | J16: 179 | K16: 339 | L16: 6.9296811
A17: 1380900000 | B17: City of Navotas | C17: 5718 | D17: 650 | E17: 675 | F17: 1325 | G17: 23.172438 | H17: 276 | I17: 21 | J17: 21 | K17: 42 | L17: 15.217391
A18: 1381000000 | B18: City of Parañaque | C18: 14517 | D18: 1267 | E18: 1221 | F18: 2488 | G18: 17.138527 | H18: 2053 | I18: 106 | J18: 93 | K18: 199 | L18: 9.693132
A19: 1381100000 | B19: Pasay City | C19: 7684 | D19: 759 | E19: 663 | F19: 1422 | G19: 18.505986 | H19: 1507 | I19: 115 | J19: 92 | K19: 207 | L19: 13.735899
A20: 1381200000 | B20: City of Pasig | C20: 19265 | D20: 2392 | E20: 2339 | F20: 4731 | G20: 24.557488 | H20: 2803 | I20: 243 | J20: 232 | K20: 475 | L20: 16.946129
A21: 1381300000 | B21: Quezon City | C21: 64737 | D21: 7835 | E21: 7662 | F21: 15497 | G21: 23.938397 | H21: -868 | I21: 781 | J21: 776 | K21: 1557 | L21: -179.37788
A22: 1381400000 | B22: City of San Juan | C22: 2363 | D22: 103 | E22: 96 | F22: 199 | G22: 8.4214981 | H22: 1266 | I22: 35 | J22: 23 | K22: 58 | L22: 4.5813586
A23: 1381500000 | B23: City of Taguig | C23: 28175 | D23: 1401 | E23: 1420 | F23: 2821 | G23: 10.012422 | H23: 17945 | I23: 918 | J23: 846 | K23: 1764 | L23: 9.8300362
A24: 1381600000 | B24: City of Valenzuela | C24: 14813 | D24: 1320 | E24: 1208 | F24: 2528 | G24: 17.066091 | H24: 7459 | I24: 92 | J24: 73 | K24: 165 | L24: 2.2120928
A25: 1381701000 | B25: Pateros | C25: 1221 | D25: 90 | E25: 90 | F25: 180 | G25: 14.742015 | H25: 368 | I25: 5 | J25: 13 | K25: 18 | L25: 4.8913043
A26: 1400000000 | B26: CAR | C26: 34199 | D26: 2711 | E26: 2586 | F26: 5297 | G26: 15.488757 | H26: 11531 | I26: 207 | J26: 190 | K26: 397 | L26: 3.4428931
A27: 1400100000 | B27: Abra | C27: 3951 | D27: 364 | E27: 367 | F27: 731 | G27: 18.501645 | H27: 758 | I27: 3 | J27: 5 | K27: 8 | L27: 1.055409
A28: 1400101000 | B28: Bangued | C28: 808 | D28: 95 | E28: 95 | F28: 190 | G28: 23.514851 | H28: 62 | I28: 0 | J28: 0 | K28: 0 | L28: 0
A29: 1400102000 | B29: Boliney | C29: 79 | D29: 8 | E29: 2 | F29: 10 | G29: 12.658228 | H29: 41 | I29: 0 | J29: 0 | K29: 0 | L29: 0
A30: 1400103000 | B30: Bucay | C30: 279 | D30: 23 | E30: 31 | F30: 54 | G30: 19.354839 | H30: 24 | I30: 3 | J30: 2 | K30: 5 | L30: 20.833333
A31: 1400104000 | B31: Bucloc | C31: 30 | D31: 5 | E31: 4 | F31: 9 | G31: 30 | H31: 17 | I31: 0 | J31: 0 | K31: 0 | L31: 0
A32: 1400105000 | B32: Daguioman | C32: 34 | D32: 0 | E32: 1 | F32: 1 | G32: 2.9411765 | H32: 9 | I32: 0 | J32: 0 | K32: 0 | L32: 0
A33: 1400106000 | B33: Danglas | C33: 60 | D33: 12 | E33: 7 | F33: 19 | G33: 31.666667 | H33: 0 | I33: 0 | J33: 0 | K33: 0 | L33: 0
A34: 1400107000 | B34: Dolores | C34: 193 | D34: 12 | E34: 17 | F34: 29 | G34: 15.025907 | H34: 20 | I34: 0 | J34: 0 | K34: 0 | L34: 0
A35: 1400108000 | B35: La Paz | C35: 268 | D35: 20 | E35: 19 | F35: 39 | G35: 14.552239 | H35: -2 | I35: 0 | J35: 0 | K35: 0 | L35: 0
A36: 1400109000 | B36: Lacub | C36: 67 | D36: 1 | E36: 7 | F36: 8 | G36: 11.940299 | H36: 42 | I36: 0 | J36: 0 | K36: 0 | L36: 0
A37: 1400110000 | B37: Lagangilang | C37: 243 | D37: 16 | E37: 26 | F37: 42 | G37: 17.283951 | H37: 46 | I37: 0 | J37: 0 | K37: 0 | L37: 0
A38: 1400111000 | B38: Lagayan | C38: 64 | D38: 7 | E38: 9 | F38: 16 | G38: 25 | H38: 3 | I38: 0 | J38: 0 | K38: 0 | L38: 0
... A54: 1400127000 | B54: Villaviciosa | C54: 91 | D54: 12 | E54: 4 | F54: 16 | G54: 17.582418 | H54: 27 | I54: 0 | J54: 0 | K54: 0 | L54: 0
A55: 1401100000 | B55: Benguet | C55: 9666 | D55: 603 | E55: 596 | F55: 1199 | G55: 12.404304 | H55: 4686 | I55: 75 | J55: 88 | K55: 163 | L55: 3.4784464
A56: 1401101000 | B56: Atok | C56: 364 | D56: 17 | E56: 24 | F56: 41 | G56: 11.263736 | H56: 174 | I56: 1 | J56: 0 | K56: 1 | L56: 0.57471264
...

Sheet Jan
A1: Immunization Services for Infants and Children
A2: Fully Immunized Children & Completely Immunized Children
A3: Philippines, 2025 January
A5: PSGC 10 | B5: Region, Province/City, and Municipality | C5: Projected Population (0-12 months old) (Previous cohort) | D5: FIC | H5: Projected population 0-12 months (previous cohort) minus previous FIC | I5: CIC
D6: Male | E6: Female | F6: Total | G6: % | I6: Male | J6: Female | K6: Total | L6: %
B7: PHILIPPINES | C7: 2392392 | D7: 63436 | E7: 61065 | F7: 124501 | G7: 5.2040385 | H7: 840855 | I7: 7033 | J7: 6619 | K7: 13652 | L7: 1.6235855
A8: 1300000000 | B8: NCR | C8: 285798 | D8: 8516 | E8: 8360 | F8: 16876 | G8: 5.9048699 | H8: 60578 | I8: 842 | J8: 792 | K8: 1634 | L8: 2.6973489
A9: 1380100000 | B9: City of Caloocan | C9: 36488 | D9: 892 | E9: 958 | F9: 1850 | G9: 5.0701601 | H9: 10459 | I9: 53 | J9: 38 | K9: 91 | L9: 0.87006406
A10: 1380200000 | B10: City of Las Piñas | C10: 12284 | D10: 366 | E10: 345 | F10: 711 | G10: 5.7880169 | H10: 2457 | I10: 39 | J10: 34 | K10: 73 | L10: 2.971103
A11: 1380300000 | B11: City of Makati | C11: 4580 | D11: 195 | E11: 157 | F11: 352 | G11: 7.6855895 | H11: 269 | I11: 7 | J11: 4 | K11: 11 | L11: 4.0892193
A12: 1380400000 | B12: City of Malabon | C12: 8070 | D12: 202 | E12: 202 | F12: 404 | G12: 5.0061958 | H12: 1806 | I12: 60 | J12: 53 | K12: 113 | L12: 6.2569214
A13: 1380500000 | B13: City of Mandaluyong | C13: 8672 | D13: 232 | E13: 256 | F13: 488 | G13: 5.6273063 | H13: 318 | I13: 10 | J13: 4 | K13: 14 | L13: 4.4025157
A14: 1380600000 | B14: City of Manila | C14: 37288 | D14: 1053 | E14: 956 | F14: 2009 | G14: 5.3877923 | H14: 1758 | I14: 3 | J14: 27 | K14: 30 | L14: 1.7064846
A15: 1380700000 | B15: City of Marikina | C15: 9135 | D15: 132 | E15: 122 | F15: 254 | G15: 2.7805145 | H15: 5810 | I15: 27 | J15: 25 | K15: 52 | L15: 0.89500861
A16: 1380800000 | B16: City of Muntinlupa | C16: 10788 | D16: 160 | E16: 184 | F16: 344 | G16: 3.1887282 | H16: 4892 | I16: 45 | J16: 56 | K16: 101 | L16: 2.0645953
A17: 1380900000 | B17: City of Navotas | C17: 5718 | D17: 192 | E17: 198 | F17: 390 | G17: 6.8205666 | H17: 276 | I17: 7 | J17: 5 | K17: 12 | L17: 4.3478261
A18: 1381000000 | B18: City of Parañaque | C18: 14517 | D18: 389 | E18: 371 | F18: 760 | G18: 5.2352414 | H18: 2053 | I18: 31 | J18: 27 | K18: 58 | L18: 2.825134
A19: 1381100000 | B19: Pasay City | C19: 7684 | D19: 278 | E19: 211 | F19: 489 | G19: 6.363873 | H19: 1507 | I19: 20 | J19: 16 | K19: 36 | L19: 2.388852
A20: 1381200000 | B20: City of Pasig | C20: 19265 | D20: 844 | E20: 850 | F20: 1694 | G20: 8.7931482 | H20: 2803 | I20: 24 | J20: 20 | K20: 44 | L20: 1.5697467
A21: 1381300000 | B21: Quezon City | C21: 64737 | D21: 2589 | E21: 2634 | F21: 5223 | G21: 8.0680291 | H21: -868 | I21: 256 | J21: 243 | K21: 499 | L21: -57.488479
A22: 1381400000 | B22: City of San Juan | C22: 2363 | D22: 42 | E22: 31 | F22: 73 | G22: 3.0892933 | H22: 1266 | I22: 12 | J22: 13 | K22: 25 | L22: 1.9747235
A23: 1381500000 | B23: City of Taguig | C23: 28175 | D23: 492 | E23: 465 | F23: 957 | G23: 3.3966282 | H23: 17945 | I23: 214 | J23: 197 | K23: 411 | L23: 2.2903316
A24: 1381600000 | B24: City of Valenzuela | C24: 14813 | D24: 428 | E24: 400 | F24: 828 | G24: 5.5896847 | H24: 7459 | I24: 33 | J24: 30 | K24: 63 | L24: 0.84461724
A25: 1381701000 | B25: Pateros | C25: 1221 | D25: 30 | E25: 20 | F25: 50 | G25: 4.0950041 | H25: 368 | I25: 1 | J25: 0 | K25: 1 | L25: 0.27173913
A26: 1400000000 | B26: CAR | C26: 34199 | D26: 987 | E26: 856 | F26: 1843 | G26: 5.3890465 | H26: 11531 | I26: 78 | J26: 72 | K26: 150 | L26: 1.3008412
A27: 1400100000 | B27: Abra | C27: 3951 | D27: 156 | E27: 150 | F27: 306 | G27: 7.7448747 | H27: 758 | I27: 0 | J27: 2 | K27: 2 | L27: 0.26385224
A28: 1400101000 | B28: Bangued | C28: 808 | D28: 32 | E28: 38 | F28: 70 | G28: 8.6633663 | H28: 62 | I28: 0 | J28: 0 | K28: 0 | L28: 0
A29: 1400102000 | B29: Boliney | C29: 79 | D29: 6 | E29: 2 | F29: 8 | G29: 10.126582 | H29: 41 | I29: 0 | J29: 0 | K29: 0 | L29: 0
A30: 1400103000 | B30: Bucay | C30: 279 | D30: 11 | E30: 11 | F30: 22 | G30: 7.8853047 | H30: 24 | I30: 0 | J30: 0 | K30: 0 | L30: 0
A31: 1400104000 | B31: Bucloc | C31: 30 | D31: 2 | E31: 1 | F31: 3 | G31: 10 | H31: 17 | I31: 0 | J31: 0 | K31: 0 | L31: 0
A32: 1400105000 | B32: Daguioman | C32: 34 | D32: 0 | E32: 1 | F32: 1 | G32: 2.9411765 | H32: 9 | I32: 0 | J32: 0 | K32: 0 | L32: 0
A33: 1400106000 | B33: Danglas | C33: 60 | D33: 6 | E33: 2 | F33: 8 | G33: 13.333333 | H33: 0 | I33: 0 | J33: 0 | K33: 0 | L33: 0
A34: 1400107000 | B34: Dolores | C34: 193 | D34: 9 | E34: 4 | F34: 13 | G34: 6.7357513 | H34: 20 | I34: 0 | J34: 0 | K34: 0 | L34: 0
A35: 1400108000 | B35: La Paz | C35: 268 | D35: 7 | E35: 9 | F35: 16 | G35: 5.9701493 | H35: -2 | I35: 0 | J35: 0 | K35: 0 | L35: 0
A36: 1400109000 | B36: Lacub | C36: 67 | D36: 1 | E36: 3 | F36: 4 | G36: 5.9701493 | H36: 42 | I36: 0 | J36: 0 | K36: 0 | L36: 0
A37: 1400110000 | B37: Lagangilang | C37: 243 | D37: 9 | E37: 10 | F37: 19 | G37: 7.81893 | H37: 46 | I37: 0 | J37: 0 | K37: 0 | L37: 0
A38: 1400111000 | B38: Lagayan | C38: 64 | D38: 3 | E38: 4 | F38: 7 | G38: 10.9375 | H38: 3 | I38: 0 | J38: 0 | K38: 0 | L38: 0
... A54: 1400127000 | B54: Villaviciosa | C54: 91 | D54: 3 | E54: 2 | F54: 5 | G54: 5.4945055 | H54: 27 | I54: 0 | J54: 0 | K54: 0 | L54: 0
A55: 1401100000 | B55: Benguet | C55: 9666 | D55: 184 | E55: 150 | F55: 334 | G55: 3.4554107 | H55: 4686 | I55: 20 | J55: 16 | K55: 36 | L55: 0.76824584
A56: 1401101000 | B56: Atok | C56: 364 | D56: 7 | E56: 8 | F56: 15 | G56: 4.1208791 | H56: 174 | I56: 0 | J56: 0 | K56: 0 | L56: 0
...

Sheet Feb
A1: Immunization Services for Infants and Children
A2: Fully Immunized Children & Completely Immunized Children
A3: Philippines, 2025 February
A5: PSGC 10 | B5: Region, Province/City, and Municipality | C5: Projected Population (0-12 months old) (Previous cohort) | D5: FIC | H5: Projected population 0-12 months (previous cohort) minus previous FIC | I5: CIC
D6: Male | E6: Female | F6: Total | G6: % | I6: Male | J6: Female | K6: Total | L6: %
B7: PHILIPPINES | C7: 2392392 | D7: 62001 | E7: 60062 | F7: 122063 | G7: 5.1021321 | H7: 840855 | I7: 7714 | J7: 7088 | K7: 14802 | L7: 1.7603511
A8: 1300000000 | B8: NCR | C8: 285798 | D8: 8914 | E8: 8695 | F8: 17609 | G8: 6.1613447 | H8: 60578 | I8: 683 | J8: 564 | K8: 1247 | L8: 2.0585031
A9: 1380100000 | B9: City of Caloocan | C9: 36488 | D9: 910 | E9: 820 | F9: 1730 | G9: 4.7412848 | H9: 10459 | I9: 39 | J9: 37 | K9: 76 | L9: 0.72664691
A10: 1380200000 | B10: City of Las Piñas | C10: 12284 | D10: 360 | E10: 363 | F10: 723 | G10: 5.885705 | H10: 2457 | I10: 44 | J10: 36 | K10: 80 | L10: 3.2560033
A11: 1380300000 | B11: City of Makati | C11: 4580 | D11: 186 | E11: 186 | F11: 372 | G11: 8.1222707 | H11: 269 | I11: 6 | J11: 7 | K11: 13 | L11: 4.8327138
A12: 1380400000 | B12: City of Malabon | C12: 8070 | D12: 171 | E12: 169 | F12: 340 | G12: 4.2131351 | H12: 1806 | I12: 32 | J12: 29 | K12: 61 | L12: 3.3776301
A13: 1380500000 | B13: City of Mandaluyong | C13: 8672 | D13: 386 | E13: 375 | F13: 761 | G13: 8.775369 | H13: 318 | I13: 13 | J13: 15 | K13: 28 | L13: 8.8050314
A14: 1380600000 | B14: City of Manila | C14: 37288 | D14: 1242 | E14: 1234 | F14: 2476 | G14: 6.640206 | H14: 1758 | I14: 10 | J14: 2 | K14: 12 | L14: 0.68259386
A15: 1380700000 | B15: City of Marikina | C15: 9135 | D15: 133 | E15: 129 | F15: 262 | G15: 2.8680898 | H15: 5810 | I15: 11 | J15: 8 | K15: 19 | L15: 0.32702238
A16: 1380800000 | B16: City of Muntinlupa | C16: 10788 | D16: 103 | E16: 126 | F16: 229 | G16: 2.122729 | H16: 4892 | I16: 31 | J16: 30 | K16: 61 | L16: 1.2469338
A17: 1380900000 | B17: City of Navotas | C17: 5718 | D17: 199 | E17: 195 | F17: 394 | G17: 6.8905212 | H17: 276 | I17: 2 | J17: 0 | K17: 2 | L17: 0.72463768
A18: 1381000000 | B18: City of Parañaque | C18: 14517 | D18: 486 | E18: 463 | F18: 949 | G18: 6.5371633 | H18: 2053 | I18: 25 | J18: 15 | K18: 40 | L18: 1.9483682
A19: 1381100000 | B19: Pasay City | C19: 7684 | D19: 223 | E19: 222 | F19: 445 | G19: 5.7912546 | H19: 1507 | I19: 21 | J19: 15 | K19: 36 | L19: 2.388852
A20: 1381200000 | B20: City of Pasig | C20: 19265 | D20: 885 | E20: 825 | F20: 1710 | G20: 8.8762004 | H20: 2803 | I20: 42 | J20: 37 | K20: 79 | L20: 2.8184088
A21: 1381300000 | B21: Quezon City | C21: 64737 | D21: 2659 | E21: 2569 | F21: 5228 | G21: 8.0757527 | H21: -868 | I21: 153 | J21: 139 | K21: 292 | L21: -33.640553
A22: 1381400000 | B22: City of San Juan | C22: 2363 | D22: 34 | E22: 32 | F22: 66 | G22: 2.7930597 | H22: 1266 | I22: 6 | J22: 1 | K22: 7 | L22: 0.55292259
A23: 1381500000 | B23: City of Taguig | C23: 28175 | D23: 442 | E23: 499 | F23: 941 | G23: 3.3398403 | H23: 17945 | I23: 215 | J23: 170 | K23: 385 | L23: 2.1454444
A24: 1381600000 | B24: City of Valenzuela | C24: 14813 | D24: 464 | E24: 449 | F24: 913 | G24: 6.163505 | H24: 7459 | I24: 30 | J24: 22 | K24: 52 | L24: 0.69714439
A25: 1381701000 | B25: Pateros | C25: 1221 | D25: 31 | E25: 39 | F25: 70 | G25: 5.7330057 | H25: 368 | I25: 3 | J25: 1 | K25: 4 | L25: 1.0869565
A26: 1400000000 | B26: CAR | C26: 34199 | D26: 946 | E26: 964 | F26: 1910 | G26: 5.5849586 | H26: 11531 | I26: 63 | J26: 57 | K26: 120 | L26: 1.040673
A27: 1400100000 | B27: Abra | C27: 3951 | D27: 105 | E27: 112 | F27: 217 | G27: 5.4922804 | H27: 758 | I27: 2 | J27: 1 | K27: 3 | L27: 0.39577836
A28: 1400101000 | B28: Bangued | C28: 808 | D28: 31 | E28: 31 | F28: 62 | G28: 7.6732673 | H28: 62 | I28: 0 | J28: 0 | K28: 0 | L28: 0
A29: 1400102000 | B29: Boliney | C29: 79 | D29: 0 | E29: 0 | F29: 0 | G29: 0 | H29: 41 | I29: 0 | J29: 0 | K29: 0 | L29: 0
A30: 1400103000 | B30: Bucay | C30: 279 | D30: 6 | E30: 12 | F30: 18 | G30: 6.4516129 | H30: 24 | I30: 2 | J30: 1 | K30: 3 | L30: 12.5
A31: 1400104000 | B31: Bucloc | C31: 30 | D31: 1 | E31: 1 | F31: 2 | G31: 6.6666667 | H31: 17 | I31: 0 | J31: 0 | K31: 0 | L31: 0
A32: 1400105000 | B32: Daguioman | C32: 34 | D32: 0 | E32: 0 | F32: 0 | G32: 0 | H32: 9 | I32: 0 | J32: 0 | K32: 0 | L32: 0
A33: 1400106000 | B33: Danglas | C33: 60 | D33: 1 | E33: 3 | F33: 4 | G33: 6.6666667 | H33: 0 | I33: 0 | J33: 0 | K33: 0 | L33: 0
A34: 1400107000 | B34: Dolores | C34: 193 | D34: 2 | E34: 9 | F34: 11 | G34: 5.6994819 | H34: 20 | I34: 0 | J34: 0 | K34: 0 | L34: 0
A35: 1400108000 | B35: La Paz | C35: 268 | D35: 8 | E35: 7 | F35: 15 | G35: 5.5970149 | H35: -2 | I35: 0 | J35: 0 | K35: 0 | L35: 0
A36: 1400109000 | B36: Lacub | C36: 67 | D36: 0 | E36: 2 | F36: 2 | G36: 2.9850746 | H36: 42 | I36: 0 | J36: 0 | K36: 0 | L36: 0
A37: 1400110000 | B37: Lagangilang | C37: 243 | D37: 3 | E37: 10 | F37: 13 | G37: 5.3497942 | H37: 46 | I37: 0 | J37: 0 | K37: 0 | L37: 0
A38: 1400111000 | B38: Lagayan | C38: 64 | D38: 3 | E38: 3 | F38: 6 | G38: 9.375 | H38: 3 | I38: 0 | J38: 0 | K38: 0 | L38: 0
... A54: 1400127000 | B54: Villaviciosa | C54: 91 | D54: 3 | E54: 0 | F54: 3 | G54: 3.2967033 | H54: 27 | I54: 0 | J54: 0 | K54: 0 | L54: 0
A55: 1401100000 | B55: Benguet | C55: 9666 | D55: 219 | E55: 247 | F55: 466 | G55: 4.8210221 | H55: 4686 | I55: 34 | J55: 39 | K55: 73 | L55: 1.5578318
A56: 1401101000 | B56: Atok | C56: 364 | D56: 6 | E56: 9 | F56: 15 | G56: 4.1208791 | H56: 174 | I56: 0 | J56: 0 | K56: 0 | L56: 0
...

Sheet Mar
A1: Immunization Services for Infants and Children
A2: Fully Immunized Children & Completely Immunized Children
A3: Philippines, 2025 March
A5: PSGC 10 | B5: Region, Province/City, and Municipality | C5: Projected Population (0-12 months old) (Previous cohort) | D5: FIC | H5: Projected population 0-12 months (previous cohort) minus previous FIC | I5: CIC
D6: Male | E6: Female | F6: Total | G6: % | I6: Male | J6: Female | K6: Total | L6: %
B7: PHILIPPINES | C7: 2392392 | D7: 61478 | E7: 59633 | F7: 121111 | G7: 5.0623393 | H7: 840855 | I7: 10407 | J7: 9556 | K7: 19963 | L7: 2.3741311
A8: 1300000000 | B8: NCR | C8: 285798 | D8: 9522 | E8: 9252 | F8: 18774 | G8: 6.5689753 | H8: 60578 | I8: 2344 | J8: 2312 | K8: 4656 | L8: 7.6859586
A9: 1380100000 | B9: City of Caloocan | C9: 36488 | D9: 1200 | E9: 1116 | F9: 2316 | G9: 6.3472923 | H9: 10459 | I9: 65 | J9: 35 | K9: 100 | L9: 0.95611435
A10: 1380200000 | B10: City of Las Piñas | C10: 12284 | D10: 428 | E10: 468 | F10: 896 | G10: 7.294041 | H10: 2457 | I10: 123 | J10: 132 | K10: 255 | L10: 10.37851
A11: 1380300000 | B11: City of Makati | C11: 4580 | D11: 189 | E11: 187 | F11: 376 | G11: 8.209607 | H11: 269 | I11: 5 | J11: 7 | K11: 12 | L11: 4.4609665
A12: 1380400000 | B12: City of Malabon | C12: 8070 | D12: 192 | E12: 155 | F12: 347 | G12: 4.2998761 | H12: 1806 | I12: 37 | J12: 46 | K12: 83 | L12: 4.5957918
A13: 1380500000 | B13: City of Mandaluyong | C13: 8672 | D13: 391 | E13: 410 | F13: 801 | G13: 9.2366236 | H13: 318 | I13: 256 | J13: 271 | K13: 527 | L13: 165.72327
A14: 1380600000 | B14: City of Manila | C14: 37288 | D14: 1681 | E14: 1707 | F14: 3388 | G14: 9.086033 | H14: 1758 | I14: 494 | J14: 466 | K14: 960 | L14: 54.607509
A15: 1380700000 | B15: City of Marikina | C15: 9135 | D15: 134 | E15: 128 | F15: 262 | G15: 2.8680898 | H15: 5810 | I15: 59 | J15: 44 | K15: 103 | L15: 1.7728055
A16: 1380800000 | B16: City of Muntinlupa | C16: 10788 | D16: 197 | E16: 180 | F16: 377 | G16: 3.4946237 | H16: 4892 | I16: 84 | J16: 93 | K16: 177 | L16: 3.6181521
A17: 1380900000 | B17: City of Navotas | C17: 5718 | D17: 259 | E17: 282 | F17: 541 | G17: 9.4613501 | H17: 276 | I17: 12 | J17: 16 | K17: 28 | L17: 10.144928
A18: 1381000000 | B18: City of Parañaque | C18: 14517 | D18: 392 | E18: 387 | F18: 779 | G18: 5.3661225 | H18: 2053 | I18: 50 | J18: 51 | K18: 101 | L18: 4.9196298
A19: 1381100000 | B19: Pasay City | C19: 7684 | D19: 258 | E19: 230 | F19: 488 | G19: 6.3508589 | H19: 1507 | I19: 74 | J19: 61 | K19: 135 | L19: 8.9581951
A20: 1381200000 | B20: City of Pasig | C20: 19265 | D20: 663 | E20: 664 | F20: 1327 | G20: 6.8881391 | H20: 2803 | I20: 177 | J20: 175 | K20: 352 | L20: 12.557974
A21: 1381300000 | B21: Quezon City | C21: 64737 | D21: 2587 | E21: 2459 | F21: 5046 | G21: 7.7946151 | H21: -868 | I21: 372 | J21: 394 | K21: 766 | L21: -88.248848
A22: 1381400000 | B22: City of San Juan | C22: 2363 | D22: 27 | E22: 33 | F22: 60 | G22: 2.5391452 | H22: 1266 | I22: 17 | J22: 9 | K22: 26 | L22: 2.0537125
A23: 1381500000 | B23: City of Taguig | C23: 28175 | D23: 467 | E23: 456 | F23: 923 | G23: 3.2759539 | H23: 17945 | I23: 489 | J23: 479 | K23: 968 | L23: 5.3942602
A24: 1381600000 | B24: City of Valenzuela | C24: 14813 | D24: 428 | E24: 359 | F24: 787 | G24: 5.3129008 | H24: 7459 | I24: 29 | J24: 21 | K24: 50 | L24: 0.67033114
A25: 1381701000 | B25: Pateros | C25: 1221 | D25: 29 | E25: 31 | F25: 60 | G25: 4.9140049 | H25: 368 | I25: 1 | J25: 12 | K25: 13 | L25: 3.5326087
A26: 1400000000 | B26: CAR | C26: 34199 | D26: 778 | E26: 766 | F26: 1544 | G26: 4.5147519 | H26: 11531 | I26: 66 | J26: 61 | K26: 127 | L26: 1.1013789
A27: 1400100000 | B27: Abra | C27: 3951 | D27: 103 | E27: 105 | F27: 208 | G27: 5.26449 | H27: 758 | I27: 1 | J27: 2 | K27: 3 | L27: 0.39577836
A28: 1400101000 | B28: Bangued | C28: 808 | D28: 32 | E28: 26 | F28: 58 | G28: 7.1782178 | H28: 62 | I28: 0 | J28: 0 | K28: 0 | L28: 0
A29: 1400102000 | B29: Boliney | C29: 79 | D29: 2 | E29: 0 | F29: 2 | G29: 2.5316456 | H29: 41 | I29: 0 | J29: 0 | K29: 0 | L29: 0
A30: 1400103000 | B30: Bucay | C30: 279 | D30: 6 | E30: 8 | F30: 14 | G30: 5.0179211 | H30: 24 | I30: 1 | J30: 1 | K30: 2 | L30: 8.3333333
A31: 1400104000 | B31: Bucloc | C31: 30 | D31: 2 | E31: 2 | F31: 4 | G31: 13.333333 | H31: 17 | I31: 0 | J31: 0 | K31: 0 | L31: 0
A32: 1400105000 | B32: Daguioman | C32: 34 | D32: 0 | E32: 0 | F32: 0 | G32: 0 | H32: 9 | I32: 0 | J32: 0 | K32: 0 | L32: 0
A33: 1400106000 | B33: Danglas | C33: 60 | D33: 5 | E33: 2 | F33: 7 | G33: 11.666667 | H33: 0 | I33: 0 | J33: 0 | K33: 0 | L33: 0
A34: 1400107000 | B34: Dolores | C34: 193 | D34: 1 | E34: 4 | F34: 5 | G34: 2.5906736 | H34: 20 | I34: 0 | J34: 0 | K34: 0 | L34: 0
A35: 1400108000 | B35: La Paz | C35: 268 | D35: 5 | E35: 3 | F35: 8 | G35: 2.9850746 | H35: -2 | I35: 0 | J35: 0 | K35: 0 | L35: 0
A36: 1400109000 | B36: Lacub | C36: 67 | D36: 0 | E36: 2 | F36: 2 | G36: 2.9850746 | H36: 42 | I36: 0 | J36: 0 | K36: 0 | L36: 0
A37: 1400110000 | B37: Lagangilang | C37: 243 | D37: 4 | E37: 6 | F37: 10 | G37: 4.1152263 | H37: 46 | I37: 0 | J37: 0 | K37: 0 | L37: 0
A38: 1400111000 | B38: Lagayan | C38: 64 | D38: 1 | E38: 2 | F38: 3 | G38: 4.6875 | H38: 3 | I38: 0 | J38: 0 | K38: 0 | L38: 0
... A54: 1400127000 | B54: Villaviciosa | C54: 91 | D54: 6 | E54: 2 | F54: 8 | G54: 8.7912088 | H54: 27 | I54: 0 | J54: 0 | K54: 0 | L54: 0
A55: 1401100000 | B55: Benguet | C55: 9666 | D55: 200 | E55: 199 | F55: 399 | G55: 4.1278709 | H55: 4686 | I55: 21 | J55: 33 | K55: 54 | L55: 1.1523688
A56: 1401101000 | B56: Atok | C56: 364 | D56: 4 | E56: 7 | F56: 11 | G56: 3.021978 | H56: 174 | I56: 1 | J56: 0 | K56: 1 | L56: 0.57471264
...

Sheet Qtr2
A1: Immunization Services for Infants and Children
A2: Fully Immunized Children & Completely Immunized Children
A3: Philippines, 2025 2nd Quarter
A5: PSGC 10 | B5: Region, Province/City, and Municipality | C5: Projected Population (0-12 months old) (Previous cohort) | D5: FIC | H5: Projected population 0-12 months (previous cohort) minus previous FIC | I5: CIC
D6: Male | E6: Female | F6: Total | G6: % | I6: Male | J6: Female | K6: Total | L6: %
B7: PHILIPPINES | C7: 2392392 | D7: =SUM(D8,D26,D110,D240,D339,D477,D625,D704,D825,D932,D1036,D1186,D1262,D1361,D1416,D1470,D1549,D1684) -> 187248 | E7: =SUM(E8,E26,E110,E240,E339,E477,E625,E704,E825,E932,E1036,E1186,E1262,E1361,E1416,E1470,E1549,E1684) -> 180701 | F7: =SUM(D7:E7) -> 367949 | G7: =IFERROR(F7/$C7*100,0) -> 15.379963 | H7: 840855 | I7: =SUM(I8,I26,I110,I240,I339,I477,I625,I704,I825,I932,I1036,I1186,I1262,I1361,I1416,I1470,I1549,I1684) -> 18137 | J7: =SUM(J8,J26,J110,J240,J339,J477,J625,J704,J825,J932,J1036,J1186,J1262,J1361,J1416,J1470,J1549,J1684) -> 16987 | K7: =SUM(I7:J7) -> 35124 | L7: =IFERROR(K7/$H7*100,0) -> 4.1771768
A8: 1300000000 | B8: NCR | C8: 285798 | D8: =SUM(D9:D25) -> 28567 | E8: =SUM(E9:E25) -> 28233 | F8: =SUM(D8:E8) -> 56800 | G8: =IFERROR(F8/$C8*100,0) -> 19.874177 | H8: 60578 | I8: =SUM(I9:I25) -> 2190 | J8: =SUM(J9:J25) -> 2215 | K8: =SUM(I8:J8) -> 4405 | L8: =IFERROR(K8/$H8*100,0) -> 7.2716168
A9: 1380100000 | B9: City of Caloocan | C9: 36488 | D9: =SUM(Apr!D9,May!D9,Jun!D9) -> 3275 | E9: =SUM(Apr!E9,May!E9,Jun!E9) -> 3164 | F9: =SUM(D9:E9) -> 6439 | G9: =IFERROR(F9/$C9*100,0) -> 17.646898 | H9: 10459 | I9: =SUM(Apr!I9,May!I9,Jun!I9) -> 89 | J9: =SUM(Apr!J9,May!J9,Jun!J9) -> 81 | K9: =SUM(I9:J9) -> 170 | L9: =IFERROR(K9/$H9*100,0) -> 1.6253944
A10: 1380200000 | B10: City of Las Piñas | C10: 12284 | D10: =SUM(Apr!D10,May!D10,Jun!D10) -> 1014 | E10: =SUM(Apr!E10,May!E10,Jun!E10) -> 1075 | F10: =SUM(D10:E10) -> 2089 | G10: =IFERROR(F10/$C10*100,0) -> 17.005861 | H10: 2457 | I10: =SUM(Apr!I10,May!I10,Jun!I10) -> 65 | J10: =SUM(Apr!J10,May!J10,Jun!J10) -> 77 | K10: =SUM(I10:J10) -> 142 | L10: =IFERROR(K10/$H10*100,0) -> 5.7794058
A11: 1380300000 | B11: City of Makati | C11: 4580 | D11: =SUM(Apr!D11,May!D11,Jun!D11) -> 573 | E11: =SUM(Apr!E11,May!E11,Jun!E11) -> 516 | F11: =SUM(D11:E11) -> 1089 | G11: =IFERROR(F11/$C11*100,0) -> 23.777293 | H11: 269 | I11: =SUM(Apr!I11,May!I11,Jun!I11) -> 16 | J11: =SUM(Apr!J11,May!J11,Jun!J11) -> 13 | K11: =SUM(I11:J11) -> 29 | L11: =IFERROR(K11/$H11*100,0) -> 10.780669
A12: 1380400000 | B12: City of Malabon | C12: 8070 | D12: =SUM(Apr!D12,May!D12,Jun!D12) -> 538 | E12: =SUM(Apr!E12,May!E12,Jun!E12) -> 457 | F12: =SUM(D12:E12) -> 995 | G12: =IFERROR(F12/$C12*100,0) -> 12.329616 | H12: 1806 | I12: =SUM(Apr!I12,May!I12,Jun!I12) -> 66 | J12: =SUM(Apr!J12,May!J12,Jun!J12) -> 70 | K12: =SUM(I12:J12) -> 136 | L12: =IFERROR(K12/$H12*100,0) -> 7.530454
A13: 1380500000 | B13: City of Mandaluyong | C13: 8672 | D13: =SUM(Apr!D13,May!D13,Jun!D13) -> 1093 | E13: =SUM(Apr!E13,May!E13,Jun!E13) -> 1087 | F13: =SUM(D13:E13) -> 2180 | G13: =IFERROR(F13/$C13*100,0) -> 25.138376 | H13: 318 | I13: =SUM(Apr!I13,May!I13,Jun!I13) -> 33 | J13: =SUM(Apr!J13,May!J13,Jun!J13) -> 42 | K13: =SUM(I13:J13) -> 75 | L13: =IFERROR(K13/$H13*100,0) -> 23.584906
A14: 1380600000 | B14: City of Manila | C14: 37288 | D14: =SUM(Apr!D14,May!D14,Jun!D14) -> 3897 | E14: =SUM(Apr!E14,May!E14,Jun!E14) -> 3722 | F14: =SUM(D14:E14) -> 7619 | G14: =IFERROR(F14/$C14*100,0) -> 20.432847 | H14: 1758 | I14: =SUM(Apr!I14,May!I14,Jun!I14) -> 350 | J14: =SUM(Apr!J14,May!J14,Jun!J14) -> 351 | K14: =SUM(I14:J14) -> 701 | L14: =IFERROR(K14/$H14*100,0) -> 39.874858
A15: 1380700000 | B15: City of Marikina | C15: 9135 | D15: =SUM(Apr!D15,May!D15,Jun!D15) -> 338 | E15: =SUM(Apr!E15,May!E15,Jun!E15) -> 355 | F15: =SUM(D15:E15) -> 693 | G15: =IFERROR(F15/$C15*100,0) -> 7.5862069 | H15: 5810 | I15: =SUM(Apr!I15,May!I15,Jun!I15) -> 52 | J15: =SUM(Apr!J15,May!J15,Jun!J15) -> 54 | K15: =SUM(I15:J15) -> 106 | L15: =IFERROR(K15/$H15*100,0) -> 1.8244406
A16: 1380800000 | B16: City of Muntinlupa | C16: 10788 | D16: =SUM(Apr!D16,May!D16,Jun!D16) -> 598 | E16: =SUM(Apr!E16,May!E16,Jun!E16) -> 549 | F16: =SUM(D16:E16) -> 1147 | G16: =IFERROR(F16/$C16*100,0) -> 10.632184 | H16: 4892 | I16: =SUM(Apr!I16,May!I16,Jun!I16) -> 116 | J16: =SUM(Apr!J16,May!J16,Jun!J16) -> 117 | K16: =SUM(I16:J16) -> 233 | L16: =IFERROR(K16/$H16*100,0) -> 4.7628782
A17: 1380900000 | B17: City of Navotas | C17: 5718 | D17: =SUM(Apr!D17,May!D17,Jun!D17) -> 566 | E17: =SUM(Apr!E17,May!E17,Jun!E17) -> 609 | F17: =SUM(D17:E17) -> 1175 | G17: =IFERROR(F17/$C17*100,0) -> 20.549143 | H17: 276 | I17: =SUM(Apr!I17,May!I17,Jun!I17) -> 61 | J17: =SUM(Apr!J17,May!J17,Jun!J17) -> 69 | K17: =SUM(I17:J17) -> 130 | L17: =IFERROR(K17/$H17*100,0) -> 47.101449
A18: 1381000000 | B18: City of Parañaque | C18: 14517 | D18: =SUM(Apr!D18,May!D18,Jun!D18) -> 1014 | E18: =SUM(Apr!E18,May!E18,Jun!E18) -> 1044 | F18: =SUM(D18:E18) -> 2058 | G18: =IFERROR(F18/$C18*100,0) -> 14.176483 | H18: 2053 | I18: =SUM(Apr!I18,May!I18,Jun!I18) -> 47 | J18: =SUM(Apr!J18,May!J18,Jun!J18) -> 45 | K18: =SUM(I18:J18) -> 92 | L18: =IFERROR(K18/$H18*100,0) -> 4.481247
A19: 1381100000 | B19: Pasay City | C19: 7684 | D19: =SUM(Apr!D19,May!D19,Jun!D19) -> 694 | E19: =SUM(Apr!E19,May!E19,Jun!E19) -> 654 | F19: =SUM(D19:E19) -> 1348 | G19: =IFERROR(F19/$C19*100,0) -> 17.542946 | H19: 1507 | I19: =SUM(Apr!I19,May!I19,Jun!I19) -> 73 | J19: =SUM(Apr!J19,May!J19,Jun!J19) -> 71 | K19: =SUM(I19:J19) -> 144 | L19: =IFERROR(K19/$H19*100,0) -> 9.5554081
A20: 1381200000 | B20: City of Pasig | C20: 19265 | D20: =SUM(Apr!D20,May!D20,Jun!D20) -> 1995 | E20: =SUM(Apr!E20,May!E20,Jun!E20) -> 2044 | F20: =SUM(D20:E20) -> 4039 | G20: =IFERROR(F20/$C20*100,0) -> 20.965481 | H20: 2803 | I20: =SUM(Apr!I20,May!I20,Jun!I20) -> 169 | J20: =SUM(Apr!J20,May!J20,Jun!J20) -> 139 | K20: =SUM(I20:J20) -> 308 | L20: =IFERROR(K20/$H20*100,0) -> 10.988227
A21: 1381300000 | B21: Quezon City | C21: 64737 | D21: =SUM(Apr!D21,May!D21,Jun!D21) -> 7475 | E21: =SUM(Apr!E21,May!E21,Jun!E21) -> 7613 | F21: =SUM(D21:E21) -> 15088 | G21: =IFERROR(F21/$C21*100,0) -> 23.30661 | H21: -868 | I21: =SUM(Apr!I21,May!I21,Jun!I21) -> 496 | J21: =SUM(Apr!J21,May!J21,Jun!J21) -> 491 | K21: =SUM(I21:J21) -> 987 | L21: =IFERROR(K21/$H21*100,0) -> -113.70968
A22: 1381400000 | B22: City of San Juan | C22: 2363 | D22: =SUM(Apr!D22,May!D22,Jun!D22) -> 124 | E22: =SUM(Apr!E22,May!E22,Jun!E22) -> 106 | F22: =SUM(D22:E22) -> 230 | G22: =IFERROR(F22/$C22*100,0) -> 9.7333898 | H22: 1266 | I22: =SUM(Apr!I22,May!I22,Jun!I22) -> 28 | J22: =SUM(Apr!J22,May!J22,Jun!J22) -> 33 | K22: =SUM(I22:J22) -> 61 | L22: =IFERROR(K22/$H22*100,0) -> 4.8183254
A23: 1381500000 | B23: City of Taguig | C23: 28175 | D23: =SUM(Apr!D23,May!D23,Jun!D23) -> 3569 | E23: =SUM(Apr!E23,May!E23,Jun!E23) -> 3586 | F23: =SUM(D23:E23) -> 7155 | G23: =IFERROR(F23/$C23*100,0) -> 25.394854 | H23: 17945 | I23: =SUM(Apr!I23,May!I23,Jun!I23) -> 455 | J23: =SUM(Apr!J23,May!J23,Jun!J23) -> 487 | K23: =SUM(I23:J23) -> 942 | L23: =IFERROR(K23/$H23*100,0) -> 5.2493731
A24: 1381600000 | B24: City of Valenzuela | C24: 14813 | D24: =SUM(Apr!D24,May!D24,Jun!D24) -> 1689 | E24: =SUM(Apr!E24,May!E24,Jun!E24) -> 1555 | F24: =SUM(D24:E24) -> 3244 | G24: =IFERROR(F24/$C24*100,0) -> 21.899683 | H24: 7459 | I24: =SUM(Apr!I24,May!I24,Jun!I24) -> 63 | J24: =SUM(Apr!J24,May!J24,Jun!J24) -> 58 | K24: =SUM(I24:J24) -> 121 | L24: =IFERROR(K24/$H24*100,0) -> 1.6222014
A25: 1381701000 | B25: Pateros | C25: 1221 | D25: =SUM(Apr!D25,May!D25,Jun!D25) -> 115 | E25: =SUM(Apr!E25,May!E25,Jun!E25) -> 97 | F25: =SUM(D25:E25) -> 212 | G25: =IFERROR(F25/$C25*100,0) -> 17.362817 | H25: 368 | I25: =SUM(Apr!I25,May!I25,Jun!I25) -> 11 | J25: =SUM(Apr!J25,May!J25,Jun!J25) -> 17 | K25: =SUM(I25:J25) -> 28 | L25: =IFERROR(K25/$H25*100,0) -> 7.6086957
A26: 1400000000 | B26: CAR | C26: 34199 | D26: =SUM(D27,D55,D69,D81,D90,D101,D109) -> 2507 | E26: =SUM(E27,E55,E69,E81,E90,E101,E109) -> 2407 | F26: =SUM(D26:E26) -> 4914 | G26: =IFERROR(F26/$C26*100,0) -> 14.368841 | H26: 11531 | I26: =SUM(I27,I55,I69,I81,I90,I101,I109) -> 190 | J26: =SUM(J27,J55,J69,J81,J90,J101,J109) -> 157 | K26: =SUM(I26:J26) -> 347 | L26: =IFERROR(K26/$H26*100,0) -> 3.0092793
A27: 1400100000 | B27: Abra | C27: 3951 | D27: =SUM(D28:D54) -> 342 | E27: =SUM(E28:E54) -> 350 | F27: =SUM(D27:E27) -> 692 | G27: =IFERROR(F27/$C27*100,0) -> 17.514553 | H27: 758 | I27: =SUM(I28:I54) -> 3 | J27: =SUM(J28:J54) -> 10 | K27: =SUM(I27:J27) -> 13 | L27: =IFERROR(K27/$H27*100,0) -> 1.7150396
A28: 1400101000 | B28: Bangued | C28: 808 | D28: =SUM(Apr!D28,May!D28,Jun!D28) -> 96 | E28: =SUM(Apr!E28,May!E28,Jun!E28) -> 98 | F28: =SUM(D28:E28) -> 194 | G28: =IFERROR(F28/$C28*100,0) -> 24.009901 | H28: 62 | I28: =SUM(Apr!I28,May!I28,Jun!I28) -> 0 | J28: =SUM(Apr!J28,May!J28,Jun!J28) -> 0 | K28: =SUM(I28:J28) -> 0 | L28: =IFERROR(K28/$H28*100,0) -> 0
A29: 1400102000 | B29: Boliney | C29: 79 | D29: =SUM(Apr!D29,May!D29,Jun!D29) -> 4 | E29: =SUM(Apr!E29,May!E29,Jun!E29) -> 1 | F29: =SUM(D29:E29) -> 5 | G29: =IFERROR(F29/$C29*100,0) -> 6.3291139 | H29: 41 | I29: =SUM(Apr!I29,May!I29,Jun!I29) -> 0 | J29: =SUM(Apr!J29,May!J29,Jun!J29) -> 2 | K29: =SUM(I29:J29) -> 2 | L29: =IFERROR(K29/$H29*100,0) -> 4.8780488
A30: 1400103000 | B30: Bucay | C30: 279 | D30: =SUM(Apr!D30,May!D30,Jun!D30) -> 29 | E30: =SUM(Apr!E30,May!E30,Jun!E30) -> 34 | F30: =SUM(D30:E30) -> 63 | G30: =IFERROR(F30/$C30*100,0) -> 22.580645 | H30: 24 | I30: =SUM(Apr!I30,May!I30,Jun!I30) -> 0 | J30: =SUM(Apr!J30,May!J30,Jun!J30) -> 0 | K30: =SUM(I30:J30) -> 0 | L30: =IFERROR(K30/$H30*100,0) -> 0
A31: 1400104000 | B31: Bucloc | C31: 30 | D31: =SUM(Apr!D31,May!D31,Jun!D31) -> 3 | E31: =SUM(Apr!E31,May!E31,Jun!E31) -> 2 | F31: =SUM(D31:E31) -> 5 | G31: =IFERROR(F31/$C31*100,0) -> 16.666667 | H31: 17 | I31: =SUM(Apr!I31,May!I31,Jun!I31) -> 0 | J31: =SUM(Apr!J31,May!J31,Jun!J31) -> 1 | K31: =SUM(I31:J31) -> 1 | L31: =IFERROR(K31/$H31*100,0) -> 5.8823529
A32: 1400105000 | B32: Daguioman | C32: 34 | D32: =SUM(Apr!D32,May!D32,Jun!D32) -> 3 | E32: =SUM(Apr!E32,May!E32,Jun!E32) -> 5 | F32: =SUM(D32:E32) -> 8 | G32: =IFERROR(F32/$C32*100,0) -> 23.529412 | H32: 9 | I32: =SUM(Apr!I32,May!I32,Jun!I32) -> 1 | J32: =SUM(Apr!J32,May!J32,Jun!J32) -> 0 | K32: =SUM(I32:J32) -> 1 | L32: =IFERROR(K32/$H32*100,0) -> 11.111111
A33: 1400106000 | B33: Danglas | C33: 60 | D33: =SUM(Apr!D33,May!D33,Jun!D33) -> 4 | E33: =SUM(Apr!E33,May!E33,Jun!E33) -> 9 | F33: =SUM(D33:E33) -> 13 | G33: =IFERROR(F33/$C33*100,0) -> 21.666667 | H33: 0 | I33: =SUM(Apr!I33,May!I33,Jun!I33) -> 0 | J33: =SUM(Apr!J33,May!J33,Jun!J33) -> 0 | K33: =SUM(I33:J33) -> 0 | L33: =IFERROR(K33/$H33*100,0) -> 0
A34: 1400107000 | B34: Dolores | C34: 193 | D34: =SUM(Apr!D34,May!D34,Jun!D34) -> 15 | E34: =SUM(Apr!E34,May!E34,Jun!E34) -> 15 | F34: =SUM(D34:E34) -> 30 | G34: =IFERROR(F34/$C34*100,0) -> 15.544041 | H34: 20 | I34: =SUM(Apr!I34,May!I34,Jun!I34) -> 0 | J34: =SUM(Apr!J34,May!J34,Jun!J34) -> 2 | K34: =SUM(I34:J34) -> 2 | L34: =IFERROR(K34/$H34*100,0) -> 10
A35: 1400108000 | B35: La Paz | C35: 268 | D35: =SUM(Apr!D35,May!D35,Jun!D35) -> 12 | E35: =SUM(Apr!E35,May!E35,Jun!E35) -> 22 | F35: =SUM(D35:E35) -> 34 | G35: =IFERROR(F35/$C35*100,0) -> 12.686567 | H35: -2 | I35: =SUM(Apr!I35,May!I35,Jun!I35) -> 0 | J35: =SUM(Apr!J35,May!J35,Jun!J35) -> 0 | K35: =SUM(I35:J35) -> 0 | L35: =IFERROR(K35/$H35*100,0) -> 0
A36: 1400109000 | B36: Lacub | C36: 67 | D36: =SUM(Apr!D36,May!D36,Jun!D36) -> 4 | E36: =SUM(Apr!E36,May!E36,Jun!E36) -> 4 | F36: =SUM(D36:E36) -> 8 | G36: =IFERROR(F36/$C36*100,0) -> 11.940299 | H36: 42 | I36: =SUM(Apr!I36,May!I36,Jun!I36) -> 0 | J36: =SUM(Apr!J36,May!J36,Jun!J36) -> 2 | K36: =SUM(I36:J36) -> 2 | L36: =IFERROR(K36/$H36*100,0) -> 4.7619048
A37: 1400110000 | B37: Lagangilang | C37: 243 | D37: =SUM(Apr!D37,May!D37,Jun!D37) -> 19 | E37: =SUM(Apr!E37,May!E37,Jun!E37) -> 11 | F37: =SUM(D37:E37) -> 30 | G37: =IFERROR(F37/$C37*100,0) -> 12.345679 | H37: 46 | I37: =SUM(Apr!I37,May!I37,Jun!I37) -> 0 | J37: =SUM(Apr!J37,May!J37,Jun!J37) -> 0 | K37: =SUM(I37:J37) -> 0 | L37: =IFERROR(K37/$H37*100,0) -> 0
A38: 1400111000 | B38: Lagayan | C38: 64 | D38: =SUM(Apr!D38,May!D38,Jun!D38) -> 4 | E38: =SUM(Apr!E38,May!E38,Jun!E38) -> 11 | F38: =SUM(D38:E38) -> 15 | G38: =IFERROR(F38/$C38*100,0) -> 23.4375 | H38: 3 | I38: =SUM(Apr!I38,May!I38,Jun!I38) -> 0 | J38: =SUM(Apr!J38,May!J38,Jun!J38) -> 0 | K38: =SUM(I38:J38) -> 0 | L38: =IFERROR(K38/$H38*100,0) -> 0
A39: 1400112000 | B39: Langiden | C39: 58 | D39: =SUM(Apr!D39,May!D39,Jun!D39) -> 5 | E39: =SUM(Apr!E39,May!E39,Jun!E39) -> 4 | F39: =SUM(D39:E39) -> 9 | G39: =IFERROR(F39/$C39*100,0) -> 15.517241 | H39: 29 | I39: =SUM(Apr!I39,May!I39,Jun!I39) -> 0 | J39: =SUM(Apr!J39,May!J39,Jun!J39) -> 0 | K39: =SUM(I39:J39) -> 0 | L39: =IFERROR(K39/$H39*100,0) -> 0
... A54: 1400127000 | B54: Villaviciosa | C54: 91 | D54: =SUM(Apr!D54,May!D54,Jun!D54) -> 9 | E54: =SUM(Apr!E54,May!E54,Jun!E54) -> 6 | F54: =SUM(D54:E54) -> 15 | G54: =IFERROR(F54/$C54*100,0) -> 16.483516 | H54: 27 | I54: =SUM(Apr!I54,May!I54,Jun!I54) -> 0 | J54: =SUM(Apr!J54,May!J54,Jun!J54) -> 0 | K54: =SUM(I54:J54) -> 0 | L54: =IFERROR(K54/$H54*100,0) -> 0
A55: 1401100000 | B55: Benguet | C55: 9666 | D55: =SUM(D56:D68) -> 581 | E55: =SUM(E56:E68) -> 526 | F55: =SUM(D55:E55) -> 1107 | G55: =IFERROR(F55/$C55*100,0) -> 11.452514 | H55: 4686 | I55: =SUM(I56:I68) -> 76 | J55: =SUM(J56:J68) -> 55 | K55: =SUM(I55:J55) -> 131 | L55: =IFERROR(K55/$H55*100,0) -> 2.7955612
...

Sheet Apr
A1: Immunization Services for Infants and Children
A2: Fully Immunized Children & Completely Immunized Children
A3: Philippines, 2025 April
A5: PSGC 10 | B5: Region, Province/City, and Municipality | C5: Projected Population (0-12 months old) (Previous cohort) | D5: FIC | H5: Projected population 0-12 months (previous cohort) minus previous FIC | I5: CIC
D6: Male | E6: Female | F6: Total | G6: % | I6: Male | J6: Female | K6: Total | L6: %
B7: PHILIPPINES | C7: 2392392 | D7: 59848 | E7: 57740 | F7: 117588 | G7: 4.9150808 | H7: 840855 | I7: 6427 | J7: 6211 | K7: 12638 | L7: 1.502994
A8: 1300000000 | B8: NCR | C8: 285798 | D8: 8738 | E8: 8692 | F8: 17430 | G8: 6.0987131 | H8: 60578 | I8: 958 | J8: 1038 | K8: 1996 | L8: 3.2949256
A9: 1380100000 | B9: City of Caloocan | C9: 36488 | D9: 950 | E9: 897 | F9: 1847 | G9: 5.0619382 | H9: 10459 | I9: 12 | J9: 21 | K9: 33 | L9: 0.31551774
A10: 1380200000 | B10: City of Las Piñas | C10: 12284 | D10: 330 | E10: 349 | F10: 679 | G10: 5.5275155 | H10: 2457 | I10: 26 | J10: 27 | K10: 53 | L10: 2.1571022
A11: 1380300000 | B11: City of Makati | C11: 4580 | D11: 190 | E11: 173 | F11: 363 | G11: 7.9257642 | H11: 269 | I11: 3 | J11: 9 | K11: 12 | L11: 4.4609665
A12: 1380400000 | B12: City of Malabon | C12: 8070 | D12: 154 | E12: 151 | F12: 305 | G12: 3.77943 | H12: 1806 | I12: 40 | J12: 36 | K12: 76 | L12: 4.2081949
A13: 1380500000 | B13: City of Mandaluyong | C13: 8672 | D13: 373 | E13: 355 | F13: 728 | G13: 8.3948339 | H13: 318 | I13: 14 | J13: 15 | K13: 29 | L13: 9.1194969
A14: 1380600000 | B14: City of Manila | C14: 37288 | D14: 1077 | E14: 1017 | F14: 2094 | G14: 5.6157477 | H14: 1758 | I14: 219 | J14: 239 | K14: 458 | L14: 26.052332
A15: 1380700000 | B15: City of Marikina | C15: 9135 | D15: 100 | E15: 111 | F15: 211 | G15: 2.3097975 | H15: 5810 | I15: 14 | J15: 20 | K15: 34 | L15: 0.58519793
A16: 1380800000 | B16: City of Muntinlupa | C16: 10788 | D16: 179 | E16: 153 | F16: 332 | G16: 3.0774935 | H16: 4892 | I16: 39 | J16: 42 | K16: 81 | L16: 1.6557645
A17: 1380900000 | B17: City of Navotas | C17: 5718 | D17: 204 | E17: 213 | F17: 417 | G17: 7.2927597 | H17: 276 | I17: 49 | J17: 57 | K17: 106 | L17: 38.405797
A18: 1381000000 | B18: City of Parañaque | C18: 14517 | D18: 302 | E18: 336 | F18: 638 | G18: 4.3948474 | H18: 2053 | I18: 11 | J18: 7 | K18: 18 | L18: 0.87676571
A19: 1381100000 | B19: Pasay City | C19: 7684 | D19: 231 | E19: 191 | F19: 422 | G19: 5.4919313 | H19: 1507 | I19: 46 | J19: 46 | K19: 92 | L19: 6.1048441
A20: 1381200000 | B20: City of Pasig | C20: 19265 | D20: 685 | E20: 699 | F20: 1384 | G20: 7.1840125 | H20: 2803 | I20: 53 | J20: 35 | K20: 88 | L20: 3.1394934
A21: 1381300000 | B21: Quezon City | C21: 64737 | D21: 2358 | E21: 2431 | F21: 4789 | G21: 7.3976242 | H21: -868 | I21: 186 | J21: 190 | K21: 376 | L21: -43.317972
A22: 1381400000 | B22: City of San Juan | C22: 2363 | D22: 47 | E22: 45 | F22: 92 | G22: 3.8933559 | H22: 1266 | I22: 20 | J22: 19 | K22: 39 | L22: 3.0805687
A23: 1381500000 | B23: City of Taguig | C23: 28175 | D23: 786 | E23: 857 | F23: 1643 | G23: 5.8314108 | H23: 17945 | I23: 187 | J23: 236 | K23: 423 | L23: 2.3572026
A24: 1381600000 | B24: City of Valenzuela | C24: 14813 | D24: 727 | E24: 667 | F24: 1394 | G24: 9.4106528 | H24: 7459 | I24: 36 | J24: 33 | K24: 69 | L24: 0.92505698
A25: 1381701000 | B25: Pateros | C25: 1221 | D25: 45 | E25: 47 | F25: 92 | G25: 7.5348075 | H25: 368 | I25: 3 | J25: 6 | K25: 9 | L25: 2.4456522
A26: 1400000000 | B26: CAR | C26: 34199 | D26: 814 | E26: 729 | F26: 1543 | G26: 4.5118278 | H26: 11531 | I26: 68 | J26: 40 | K26: 108 | L26: 0.93660567
A27: 1400100000 | B27: Abra | C27: 3951 | D27: 105 | E27: 118 | F27: 223 | G27: 5.6441407 | H27: 758 | I27: 2 | J27: 6 | K27: 8 | L27: 1.055409
A28: 1400101000 | B28: Bangued | C28: 808 | D28: 31 | E28: 33 | F28: 64 | G28: 7.9207921 | H28: 62 | I28: 0 | J28: 0 | K28: 0 | L28: 0
A29: 1400102000 | B29: Boliney | C29: 79 | D29: 0 | E29: 0 | F29: 0 | G29: 0 | H29: 41 | I29: 0 | J29: 1 | K29: 1 | L29: 2.4390244
A30: 1400103000 | B30: Bucay | C30: 279 | D30: 5 | E30: 15 | F30: 20 | G30: 7.1684588 | H30: 24 | I30: 0 | J30: 0 | K30: 0 | L30: 0
A31: 1400104000 | B31: Bucloc | C31: 30 | D31: 1 | E31: 0 | F31: 1 | G31: 3.3333333 | H31: 17 | I31: 0 | J31: 1 | K31: 1 | L31: 5.8823529
A32: 1400105000 | B32: Daguioman | C32: 34 | D32: 0 | E32: 1 | F32: 1 | G32: 2.9411765 | H32: 9 | I32: 0 | J32: 0 | K32: 0 | L32: 0
A33: 1400106000 | B33: Danglas | C33: 60 | D33: 3 | E33: 2 | F33: 5 | G33: 8.3333333 | H33: 0 | I33: 0 | J33: 0 | K33: 0 | L33: 0
A34: 1400107000 | B34: Dolores | C34: 193 | D34: 4 | E34: 7 | F34: 11 | G34: 5.6994819 | H34: 20 | I34: 0 | J34: 1 | K34: 1 | L34: 5
A35: 1400108000 | B35: La Paz | C35: 268 | D35: 3 | E35: 9 | F35: 12 | G35: 4.4776119 | H35: -2 | I35: 0 | J35: 0 | K35: 0 | L35: 0
A36: 1400109000 | B36: Lacub | C36: 67 | D36: 4 | E36: 2 | F36: 6 | G36: 8.9552239 | H36: 42 | I36: 0 | J36: 2 | K36: 2 | L36: 4.7619048
A37: 1400110000 | B37: Lagangilang | C37: 243 | D37: 5 | E37: 6 | F37: 11 | G37: 4.526749 | H37: 46 | I37: 0 | J37: 0 | K37: 0 | L37: 0
A38: 1400111000 | B38: Lagayan | C38: 64 | D38: 1 | E38: 2 | F38: 3 | G38: 4.6875 | H38: 3 | I38: 0 | J38: 0 | K38: 0 | L38: 0
... A54: 1400127000 | B54: Villaviciosa | C54: 91 | D54: 3 | E54: 2 | F54: 5 | G54: 5.4945055 | H54: 27 | I54: 0 | J54: 0 | K54: 0 | L54: 0
A55: 1401100000 | B55: Benguet | C55: 9666 | D55: 193 | E55: 163 | F55: 356 | G55: 3.6830126 | H55: 4686 | I55: 25 | J55: 13 | K55: 38 | L55: 0.81092616
A56: 1401101000 | B56: Atok | C56: 364 | D56: 6 | E56: 6 | F56: 12 | G56: 3.2967033 | H56: 174 | I56: 1 | J56: 0 | K56: 1 | L56: 0.57471264
...

Sheet May
A1: Immunization Services for Infants and Children
A2: Fully Immunized Children & Completely Immunized Children
A3: Philippines, 2025 May
A5: PSGC 10 | B5: Region, Province/City, and Municipality | C5: Projected Population (0-12 months old) (Previous cohort) | D5: FIC | H5: Projected population 0-12 months (previous cohort) minus previous FIC | I5: CIC
D6: Male | E6: Female | F6: Total | G6: % | I6: Male | J6: Female | K6: Total | L6: %
B7: PHILIPPINES | C7: 2392392 | D7: 63631 | E7: 61462 | F7: 125093 | G7: 5.2287836 | H7: 840855 | I7: 6264 | J7: 5762 | K7: 12026 | L7: 1.4302109
A8: 1300000000 | B8: NCR | C8: 285798 | D8: 10000 | E8: 9809 | F8: 19809 | G8: 6.9311192 | H8: 60578 | I8: 697 | J8: 668 | K8: 1365 | L8: 2.2532933
A9: 1380100000 | B9: City of Caloocan | C9: 36488 | D9: 1146 | E9: 1082 | F9: 2228 | G9: 6.1061171 | H9: 10459 | I9: 16 | J9: 13 | K9: 29 | L9: 0.27727316
A10: 1380200000 | B10: City of Las Piñas | C10: 12284 | D10: 342 | E10: 347 | F10: 689 | G10: 5.6089222 | H10: 2457 | I10: 22 | J10: 31 | K10: 53 | L10: 2.1571022
A11: 1380300000 | B11: City of Makati | C11: 4580 | D11: 186 | E11: 192 | F11: 378 | G11: 8.2532751 | H11: 269 | I11: 5 | J11: 4 | K11: 9 | L11: 3.3457249
A12: 1380400000 | B12: City of Malabon | C12: 8070 | D12: 195 | E12: 146 | F12: 341 | G12: 4.2255266 | H12: 1806 | I12: 7 | J12: 14 | K12: 21 | L12: 1.1627907
A13: 1380500000 | B13: City of Mandaluyong | C13: 8672 | D13: 360 | E13: 369 | F13: 729 | G13: 8.4063653 | H13: 318 | I13: 8 | J13: 15 | K13: 23 | L13: 7.2327044
A14: 1380600000 | B14: City of Manila | C14: 37288 | D14: 1442 | E14: 1414 | F14: 2856 | G14: 7.6593006 | H14: 1758 | I14: 69 | J14: 54 | K14: 123 | L14: 6.996587
A15: 1380700000 | B15: City of Marikina | C15: 9135 | D15: 100 | E15: 115 | F15: 215 | G15: 2.3535851 | H15: 5810 | I15: 23 | J15: 18 | K15: 41 | L15: 0.70567986
A16: 1380800000 | B16: City of Muntinlupa | C16: 10788 | D16: 216 | E16: 209 | F16: 425 | G16: 3.9395625 | H16: 4892 | I16: 41 | J16: 37 | K16: 78 | L16: 1.5944399
A17: 1380900000 | B17: City of Navotas | C17: 5718 | D17: 186 | E17: 192 | F17: 378 | G17: 6.610703 | H17: 276 | I17: 9 | J17: 10 | K17: 19 | L17: 6.884058
A18: 1381000000 | B18: City of Parañaque | C18: 14517 | D18: 393 | E18: 408 | F18: 801 | G18: 5.5176689 | H18: 2053 | I18: 23 | J18: 20 | K18: 43 | L18: 2.0944959
A19: 1381100000 | B19: Pasay City | C19: 7684 | D19: 222 | E19: 238 | F19: 460 | G19: 5.9864654 | H19: 1507 | I19: 12 | J19: 15 | K19: 27 | L19: 1.791639
A20: 1381200000 | B20: City of Pasig | C20: 19265 | D20: 706 | E20: 755 | F20: 1461 | G20: 7.583701 | H20: 2803 | I20: 109 | J20: 89 | K20: 198 | L20: 7.0638601
A21: 1381300000 | B21: Quezon City | C21: 64737 | D21: 2554 | E21: 2518 | F21: 5072 | G21: 7.8347776 | H21: -868 | I21: 161 | J21: 157 | K21: 318 | L21: -36.635945
A22: 1381400000 | B22: City of San Juan | C22: 2363 | D22: 26 | E22: 29 | F22: 55 | G22: 2.3275497 | H22: 1266 | I22: 4 | J22: 8 | K22: 12 | L22: 0.9478673
A23: 1381500000 | B23: City of Taguig | C23: 28175 | D23: 1382 | E23: 1333 | F23: 2715 | G23: 9.6362023 | H23: 17945 | I23: 172 | J23: 161 | K23: 333 | L23: 1.8556701
A24: 1381600000 | B24: City of Valenzuela | C24: 14813 | D24: 502 | E24: 429 | F24: 931 | G24: 6.2850199 | H24: 7459 | I24: 12 | J24: 12 | K24: 24 | L24: 0.32175895
A25: 1381701000 | B25: Pateros | C25: 1221 | D25: 42 | E25: 33 | F25: 75 | G25: 6.1425061 | H25: 368 | I25: 4 | J25: 10 | K25: 14 | L25: 3.8043478
A26: 1400000000 | B26: CAR | C26: 34199 | D26: 797 | E26: 845 | F26: 1642 | G26: 4.80131 | H26: 11531 | I26: 60 | J26: 60 | K26: 120 | L26: 1.040673
A27: 1400100000 | B27: Abra | C27: 3951 | D27: 107 | E27: 105 | F27: 212 | G27: 5.3657302 | H27: 758 | I27: 0 | J27: 1 | K27: 1 | L27: 0.13192612
A28: 1400101000 | B28: Bangued | C28: 808 | D28: 25 | E28: 32 | F28: 57 | G28: 7.0544554 | H28: 62 | I28: 0 | J28: 0 | K28: 0 | L28: 0
A29: 1400102000 | B29: Boliney | C29: 79 | D29: 2 | E29: 0 | F29: 2 | G29: 2.5316456 | H29: 41 | I29: 0 | J29: 0 | K29: 0 | L29: 0
A30: 1400103000 | B30: Bucay | C30: 279 | D30: 10 | E30: 7 | F30: 17 | G30: 6.09319 | H30: 24 | I30: 0 | J30: 0 | K30: 0 | L30: 0
A31: 1400104000 | B31: Bucloc | C31: 30 | D31: 2 | E31: 2 | F31: 4 | G31: 13.333333 | H31: 17 | I31: 0 | J31: 0 | K31: 0 | L31: 0
A32: 1400105000 | B32: Daguioman | C32: 34 | D32: 2 | E32: 3 | F32: 5 | G32: 14.705882 | H32: 9 | I32: 0 | J32: 0 | K32: 0 | L32: 0
A33: 1400106000 | B33: Danglas | C33: 60 | D33: 1 | E33: 4 | F33: 5 | G33: 8.3333333 | H33: 0 | I33: 0 | J33: 0 | K33: 0 | L33: 0
A34: 1400107000 | B34: Dolores | C34: 193 | D34: 3 | E34: 2 | F34: 5 | G34: 2.5906736 | H34: 20 | I34: 0 | J34: 0 | K34: 0 | L34: 0
A35: 1400108000 | B35: La Paz | C35: 268 | D35: 3 | E35: 6 | F35: 9 | G35: 3.358209 | H35: -2 | I35: 0 | J35: 0 | K35: 0 | L35: 0
A36: 1400109000 | B36: Lacub | C36: 67 | D36: 0 | E36: 2 | F36: 2 | G36: 2.9850746 | H36: 42 | I36: 0 | J36: 0 | K36: 0 | L36: 0
A37: 1400110000 | B37: Lagangilang | C37: 243 | D37: 6 | E37: 3 | F37: 9 | G37: 3.7037037 | H37: 46 | I37: 0 | J37: 0 | K37: 0 | L37: 0
A38: 1400111000 | B38: Lagayan | C38: 64 | D38: 1 | E38: 2 | F38: 3 | G38: 4.6875 | H38: 3 | I38: 0 | J38: 0 | K38: 0 | L38: 0
... A54: 1400127000 | B54: Villaviciosa | C54: 91 | D54: 4 | E54: 3 | F54: 7 | G54: 7.6923077 | H54: 27 | I54: 0 | J54: 0 | K54: 0 | L54: 0
A55: 1401100000 | B55: Benguet | C55: 9666 | D55: 200 | E55: 188 | F55: 388 | G55: 4.0140699 | H55: 4686 | I55: 26 | J55: 23 | K55: 49 | L55: 1.0456679
A56: 1401101000 | B56: Atok | C56: 364 | D56: 8 | E56: 9 | F56: 17 | G56: 4.6703297 | H56: 174 | I56: 0 | J56: 0 | K56: 0 | L56: 0
...

Sheet Jun
A1: Immunization Services for Infants and Children
A2: Fully Immunized Children & Completely Immunized Children
A3: Philippines, 2025 June
A5: PSGC 10 | B5: Region, Province/City, and Municipality | C5: Projected Population (0-12 months old) (Previous cohort) | D5: FIC | H5: Projected population 0-12 months (previous cohort) minus previous FIC | I5: CIC
D6: Male | E6: Female | F6: Total | G6: % | I6: Male | J6: Female | K6: Total | L6: %
B7: PHILIPPINES | C7: 2392392 | D7: 63769 | E7: 61499 | F7: 125268 | G7: 5.2360984 | H7: 840855 | I7: 5446 | J7: 5014 | K7: 10460 | L7: 1.2439719
A8: 1300000000 | B8: NCR | C8: 285798 | D8: 9829 | E8: 9732 | F8: 19561 | G8: 6.8443446 | H8: 60578 | I8: 535 | J8: 509 | K8: 1044 | L8: 1.7233979
A9: 1380100000 | B9: City of Caloocan | C9: 36488 | D9: 1179 | E9: 1185 | F9: 2364 | G9: 6.4788424 | H9: 10459 | I9: 61 | J9: 47 | K9: 108 | L9: 1.0326035
A10: 1380200000 | B10: City of Las Piñas | C10: 12284 | D10: 342 | E10: 379 | F10: 721 | G10: 5.8694236 | H10: 2457 | I10: 17 | J10: 19 | K10: 36 | L10: 1.4652015
A11: 1380300000 | B11: City of Makati | C11: 4580 | D11: 197 | E11: 151 | F11: 348 | G11: 7.5982533 | H11: 269 | I11: 8 | J11: 0 | K11: 8 | L11: 2.9739777
A12: 1380400000 | B12: City of Malabon | C12: 8070 | D12: 189 | E12: 160 | F12: 349 | G12: 4.3246592 | H12: 1806 | I12: 19 | J12: 20 | K12: 39 | L12: 2.1594684
A13: 1380500000 | B13: City of Mandaluyong | C13: 8672 | D13: 360 | E13: 363 | F13: 723 | G13: 8.3371771 | H13: 318 | I13: 11 | J13: 12 | K13: 23 | L13: 7.2327044
A14: 1380600000 | B14: City of Manila | C14: 37288 | D14: 1378 | E14: 1291 | F14: 2669 | G14: 7.1577988 | H14: 1758 | I14: 62 | J14: 58 | K14: 120 | L14: 6.8259386
A15: 1380700000 | B15: City of Marikina | C15: 9135 | D15: 138 | E15: 129 | F15: 267 | G15: 2.9228243 | H15: 5810 | I15: 15 | J15: 16 | K15: 31 | L15: 0.53356282
A16: 1380800000 | B16: City of Muntinlupa | C16: 10788 | D16: 203 | E16: 187 | F16: 390 | G16: 3.6151279 | H16: 4892 | I16: 36 | J16: 38 | K16: 74 | L16: 1.5126738
A17: 1380900000 | B17: City of Navotas | C17: 5718 | D17: 176 | E17: 204 | F17: 380 | G17: 6.6456803 | H17: 276 | I17: 3 | J17: 2 | K17: 5 | L17: 1.8115942
A18: 1381000000 | B18: City of Parañaque | C18: 14517 | D18: 319 | E18: 300 | F18: 619 | G18: 4.2639664 | H18: 2053 | I18: 13 | J18: 18 | K18: 31 | L18: 1.5099854
A19: 1381100000 | B19: Pasay City | C19: 7684 | D19: 241 | E19: 225 | F19: 466 | G19: 6.0645497 | H19: 1507 | I19: 15 | J19: 10 | K19: 25 | L19: 1.658925
A20: 1381200000 | B20: City of Pasig | C20: 19265 | D20: 604 | E20: 590 | F20: 1194 | G20: 6.197768 | H20: 2803 | I20: 7 | J20: 15 | K20: 22 | L20: 0.78487335
A21: 1381300000 | B21: Quezon City | C21: 64737 | D21: 2563 | E21: 2664 | F21: 5227 | G21: 8.0742079 | H21: -868 | I21: 149 | J21: 144 | K21: 293 | L21: -33.75576
A22: 1381400000 | B22: City of San Juan | C22: 2363 | D22: 51 | E22: 32 | F22: 83 | G22: 3.5124841 | H22: 1266 | I22: 4 | J22: 6 | K22: 10 | L22: 0.78988942
A23: 1381500000 | B23: City of Taguig | C23: 28175 | D23: 1401 | E23: 1396 | F23: 2797 | G23: 9.9272405 | H23: 17945 | I23: 96 | J23: 90 | K23: 186 | L23: 1.0365004
A24: 1381600000 | B24: City of Valenzuela | C24: 14813 | D24: 460 | E24: 459 | F24: 919 | G24: 6.20401 | H24: 7459 | I24: 15 | J24: 13 | K24: 28 | L24: 0.37538544
A25: 1381701000 | B25: Pateros | C25: 1221 | D25: 28 | E25: 17 | F25: 45 | G25: 3.6855037 | H25: 368 | I25: 4 | J25: 1 | K25: 5 | L25: 1.3586957
A26: 1400000000 | B26: CAR | C26: 34199 | D26: 896 | E26: 833 | F26: 1729 | G26: 5.0557034 | H26: 11531 | I26: 62 | J26: 57 | K26: 119 | L26: 1.0320007
A27: 1400100000 | B27: Abra | C27: 3951 | D27: 130 | E27: 127 | F27: 257 | G27: 6.5046824 | H27: 758 | I27: 1 | J27: 3 | K27: 4 | L27: 0.52770449
A28: 1400101000 | B28: Bangued | C28: 808 | D28: 40 | E28: 33 | F28: 73 | G28: 9.0346535 | H28: 62 | I28: 0 | J28: 0 | K28: 0 | L28: 0
A29: 1400102000 | B29: Boliney | C29: 79 | D29: 2 | E29: 1 | F29: 3 | G29: 3.7974684 | H29: 41 | I29: 0 | J29: 1 | K29: 1 | L29: 2.4390244
A30: 1400103000 | B30: Bucay | C30: 279 | D30: 14 | E30: 12 | F30: 26 | G30: 9.3189964 | H30: 24 | I30: 0 | J30: 0 | K30: 0 | L30: 0
A31: 1400104000 | B31: Bucloc | C31: 30 | D31: 0 | E31: 0 | F31: 0 | G31: 0 | H31: 17 | I31: 0 | J31: 0 | K31: 0 | L31: 0
A32: 1400105000 | B32: Daguioman | C32: 34 | D32: 1 | E32: 1 | F32: 2 | G32: 5.8823529 | H32: 9 | I32: 1 | J32: 0 | K32: 1 | L32: 11.111111
A33: 1400106000 | B33: Danglas | C33: 60 | D33: 0 | E33: 3 | F33: 3 | G33: 5 | H33: 0 | I33: 0 | J33: 0 | K33: 0 | L33: 0
A34: 1400107000 | B34: Dolores | C34: 193 | D34: 8 | E34: 6 | F34: 14 | G34: 7.253886 | H34: 20 | I34: 0 | J34: 1 | K34: 1 | L34: 5
A35: 1400108000 | B35: La Paz | C35: 268 | D35: 6 | E35: 7 | F35: 13 | G35: 4.8507463 | H35: -2 | I35: 0 | J35: 0 | K35: 0 | L35: 0
A36: 1400109000 | B36: Lacub | C36: 67 | D36: 0 | E36: 0 | F36: 0 | G36: 0 | H36: 42 | I36: 0 | J36: 0 | K36: 0 | L36: 0
A37: 1400110000 | B37: Lagangilang | C37: 243 | D37: 8 | E37: 2 | F37: 10 | G37: 4.1152263 | H37: 46 | I37: 0 | J37: 0 | K37: 0 | L37: 0
A38: 1400111000 | B38: Lagayan | C38: 64 | D38: 2 | E38: 7 | F38: 9 | G38: 14.0625 | H38: 3 | I38: 0 | J38: 0 | K38: 0 | L38: 0
... A54: 1400127000 | B54: Villaviciosa | C54: 91 | D54: 2 | E54: 1 | F54: 3 | G54: 3.2967033 | H54: 27 | I54: 0 | J54: 0 | K54: 0 | L54: 0
A55: 1401100000 | B55: Benguet | C55: 9666 | D55: 188 | E55: 175 | F55: 363 | G55: 3.7554314 | H55: 4686 | I55: 25 | J55: 19 | K55: 44 | L55: 0.93896714
A56: 1401101000 | B56: Atok | C56: 364 | D56: 9 | E56: 7 | F56: 16 | G56: 4.3956044 | H56: 174 | I56: 1 | J56: 0 | K56: 1 | L56: 0.57471264
...

Sheet Qtr3
A1: Immunization Services for Infants and Children
A2: Fully Immunized Children & Completely Immunized Children
A3: Philippines, 2025 3rd Quarter
A5: PSGC 10 | B5: Region, Province/City, and Municipality | C5: Projected Population (0-12 months old) (Previous cohort) | D5: FIC | H5: Projected population 0-12 months (previous cohort) minus previous FIC | I5: CIC
D6: Male | E6: Female | F6: Total | G6: % | I6: Male | J6: Female | K6: Total | L6: %
B7: PHILIPPINES | C7: 2392392 | D7: 198049 | E7: 189269 | F7: 387318 | G7: 16.189571 | H7: 840855 | I7: 13332 | J7: 12149 | K7: 25481 | L7: 3.0303679
A8: 1300000000 | B8: NCR | C8: 285798 | D8: 28957 | E8: 28073 | F8: 57030 | G8: 19.954653 | H8: 60578 | I8: 1379 | J8: 1342 | K8: 2721 | L8: 4.4917297
A9: 1380100000 | B9: City of Caloocan | C9: 36488 | D9: 3041 | E9: 2906 | F9: 5947 | G9: 16.298509 | H9: 10459 | I9: 101 | J9: 98 | K9: 199 | L9: 1.9026676
A10: 1380200000 | B10: City of Las Piñas | C10: 12284 | D10: 1157 | E10: 1116 | F10: 2273 | G10: 18.503745 | H10: 2457 | I10: 46 | J10: 49 | K10: 95 | L10: 3.8665039
A11: 1380300000 | B11: City of Makati | C11: 4580 | D11: 571 | E11: 527 | F11: 1098 | G11: 23.973799 | H11: 269 | I11: 7 | J11: 14 | K11: 21 | L11: 7.8066914
A12: 1380400000 | B12: City of Malabon | C12: 8070 | D12: 580 | E12: 579 | F12: 1159 | G12: 14.361834 | H12: 1806 | I12: 63 | J12: 65 | K12: 128 | L12: 7.0874862
A13: 1380500000 | B13: City of Mandaluyong | C13: 8672 | D13: 950 | E13: 960 | F13: 1910 | G13: 22.024908 | H13: 318 | I13: 17 | J13: 18 | K13: 35 | L13: 11.006289
A14: 1380600000 | B14: City of Manila | C14: 37288 | D14: 4840 | E14: 4626 | F14: 9466 | G14: 25.386183 | H14: 1758 | I14: 245 | J14: 228 | K14: 473 | L14: 26.905575
A15: 1380700000 | B15: City of Marikina | C15: 9135 | D15: 391 | E15: 415 | F15: 806 | G15: 8.8232074 | H15: 5810 | I15: 51 | J15: 59 | K15: 110 | L15: 1.8932874
A16: 1380800000 | B16: City of Muntinlupa | C16: 10788 | D16: 295 | E16: 308 | F16: 603 | G16: 5.5895439 | H16: 4892 | I16: 31 | J16: 22 | K16: 53 | L16: 1.0834015
A17: 1380900000 | B17: City of Navotas | C17: 5718 | D17: 442 | E17: 460 | F17: 902 | G17: 15.774746 | H17: 276 | I17: 4 | J17: 2 | K17: 6 | L17: 2.173913
A18: 1381000000 | B18: City of Parañaque | C18: 14517 | D18: 1702 | E18: 1727 | F18: 3429 | G18: 23.620583 | H18: 2053 | I18: 63 | J18: 48 | K18: 111 | L18: 5.4067219
A19: 1381100000 | B19: Pasay City | C19: 7684 | D19: 833 | E19: 830 | F19: 1663 | G19: 21.642374 | H19: 1507 | I19: 32 | J19: 39 | K19: 71 | L19: 4.711347
A20: 1381200000 | B20: City of Pasig | C20: 19265 | D20: 2447 | E20: 2344 | F20: 4791 | G20: 24.868933 | H20: 2803 | I20: 47 | J20: 43 | K20: 90 | L20: 3.2108455
A21: 1381300000 | B21: Quezon City | C21: 64737 | D21: 7756 | E21: 7661 | F21: 15417 | G21: 23.81482 | H21: -868 | I21: 379 | J21: 358 | K21: 737 | L21: -84.907834
A22: 1381400000 | B22: City of San Juan | C22: 2363 | D22: 167 | E22: 147 | F22: 314 | G22: 13.288193 | H22: 1266 | I22: 11 | J22: 2 | K22: 13 | L22: 1.0268562
A23: 1381500000 | B23: City of Taguig | C23: 28175 | D23: 2339 | E23: 2043 | F23: 4382 | G23: 15.552795 | H23: 17945 | I23: 273 | J23: 268 | K23: 541 | L23: 3.0147673
A24: 1381600000 | B24: City of Valenzuela | C24: 14813 | D24: 1348 | E24: 1320 | F24: 2668 | G24: 18.011206 | H24: 7459 | I24: 8 | J24: 20 | K24: 28 | L24: 0.37538544
A25: 1381701000 | B25: Pateros | C25: 1221 | D25: 98 | E25: 104 | F25: 202 | G25: 16.543817 | H25: 368 | I25: 1 | J25: 9 | K25: 10 | L25: 2.7173913
A26: 1400000000 | B26: CAR | C26: 34199 | D26: 2764 | E26: 2461 | F26: 5225 | G26: 15.278225 | H26: 11531 | I26: 171 | J26: 150 | K26: 321 | L26: 2.7838002
A27: 1400100000 | B27: Abra | C27: 3951 | D27: 434 | E27: 329 | F27: 763 | G27: 19.311567 | H27: 758 | I27: 3 | J27: 2 | K27: 5 | L27: 0.65963061
A28: 1400101000 | B28: Bangued | C28: 808 | D28: 109 | E28: 101 | F28: 210 | G28: 25.990099 | H28: 62 | I28: 0 | J28: 0 | K28: 0 | L28: 0
A29: 1400102000 | B29: Boliney | C29: 79 | D29: 6 | E29: 3 | F29: 9 | G29: 11.392405 | H29: 41 | I29: 0 | J29: 0 | K29: 0 | L29: 0
A30: 1400103000 | B30: Bucay | C30: 279 | D30: 34 | E30: 19 | F30: 53 | G30: 18.996416 | H30: 24 | I30: 0 | J30: 0 | K30: 0 | L30: 0
A31: 1400104000 | B31: Bucloc | C31: 30 | D31: 2 | E31: 4 | F31: 6 | G31: 20 | H31: 17 | I31: 0 | J31: 0 | K31: 0 | L31: 0
A32: 1400105000 | B32: Daguioman | C32: 34 | D32: 3 | E32: 1 | F32: 4 | G32: 11.764706 | H32: 9 | I32: 1 | J32: 0 | K32: 1 | L32: 11.111111
A33: 1400106000 | B33: Danglas | C33: 60 | D33: 7 | E33: 12 | F33: 19 | G33: 31.666667 | H33: 0 | I33: 0 | J33: 0 | K33: 0 | L33: 0
A34: 1400107000 | B34: Dolores | C34: 193 | D34: 27 | E34: 23 | F34: 50 | G34: 25.906736 | H34: 20 | I34: 1 | J34: 0 | K34: 1 | L34: 5
A35: 1400108000 | B35: La Paz | C35: 268 | D35: 20 | E35: 16 | F35: 36 | G35: 13.432836 | H35: -2 | I35: 0 | J35: 0 | K35: 0 | L35: 0
A36: 1400109000 | B36: Lacub | C36: 67 | D36: 7 | E36: 1 | F36: 8 | G36: 11.940299 | H36: 42 | I36: 0 | J36: 0 | K36: 0 | L36: 0
A37: 1400110000 | B37: Lagangilang | C37: 243 | D37: 20 | E37: 21 | F37: 41 | G37: 16.872428 | H37: 46 | I37: 0 | J37: 0 | K37: 0 | L37: 0
A38: 1400111000 | B38: Lagayan | C38: 64 | D38: 9 | E38: 7 | F38: 16 | G38: 25 | H38: 3 | I38: 0 | J38: 0 | K38: 0 | L38: 0
... A54: 1400127000 | B54: Villaviciosa | C54: 91 | D54: 6 | E54: 7 | F54: 13 | G54: 14.285714 | H54: 27 | I54: 0 | J54: 0 | K54: 0 | L54: 0
A55: 1401100000 | B55: Benguet | C55: 9666 | D55: 606 | E55: 572 | F55: 1178 | G55: 12.187047 | H55: 4686 | I55: 78 | J55: 60 | K55: 138 | L55: 2.9449424
A56: 1401101000 | B56: Atok | C56: 364 | D56: 27 | E56: 28 | F56: 55 | G56: 15.10989 | H56: 174 | I56: 0 | J56: 2 | K56: 2 | L56: 1.1494253
...

Sheet Jul
A1: Immunization Services for Infants and Children
A2: Fully Immunized Children & Completely Immunized Children
A3: Philippines, 2025 July
A5: PSGC 10 | B5: Region, Province/City, and Municipality | C5: Projected Population (0-12 months old) (Previous cohort) | D5: FIC | H5: Projected population 0-12 months (previous cohort) minus previous FIC | I5: CIC
D6: Male | E6: Female | F6: Total | G6: % | I6: Male | J6: Female | K6: Total | L6: %
B7: PHILIPPINES | C7: 2392392 | D7: 63658 | E7: 60425 | F7: 124083 | G7: 5.1865664 | H7: 840855 | I7: 4721 | J7: 4305 | K7: 9026 | L7: 1.0734312
A8: 1300000000 | B8: NCR | C8: 285798 | D8: 9364 | E8: 9032 | F8: 18396 | G8: 6.436714 | H8: 60578 | I8: 439 | J8: 456 | K8: 895 | L8: 1.4774341
A9: 1380100000 | B9: City of Caloocan | C9: 36488 | D9: 948 | E9: 913 | F9: 1861 | G9: 5.100307 | H9: 10459 | I9: 31 | J9: 32 | K9: 63 | L9: 0.60235204
A10: 1380200000 | B10: City of Las Piñas | C10: 12284 | D10: 374 | E10: 403 | F10: 777 | G10: 6.3253012 | H10: 2457 | I10: 16 | J10: 14 | K10: 30 | L10: 1.2210012
